<?xml version="1.0" encoding="utf-8"?>
<!-- MSG Gripper only  PAR6 robot arm links removed -->
<robot
  name="msg_gripper">
  <link
    name="gripper">
    <inertial>
      <origin
        xyz="-0.00642470048892474 0.000282668798476438 -0.0695192335056825"
        rpy="0 0 0" />
      <mass
        value="0.167623200457379" />
      <inertia
        ixx="0.000140871735417615"
        ixy="-9.82778432876683E-07"
        ixz="-2.72691487145471E-06"
        iyy="2.45392416247037E-05"
        iyz="-2.78909378823719E-07"
        izz="0.00013036472950858" />
    </inertial>
    <visual>
      <origin
        xyz="0 0 0"
        rpy="0 0 0" />
      <geometry>
        <mesh
          filename="package://msg_gripper/meshes/gripper.STL" />
      </geometry>
      <material
        name="">
        <color
          rgba="0.792156862745098 0.819607843137255 0.933333333333333 1" />
      </material>
    </visual>
    <collision>
      <origin
        xyz="0 0 0"
        rpy="0 0 0" />
      <geometry>
        <mesh
          filename="package://msg_gripper/meshes/gripper.STL" />
      </geometry>
    </collision>
  </link>
  <link
    name="jaw1">
    <inertial>
      <origin
        xyz="0.000317390129572659 -0.0636011550113124 -0.0505219142777576"
        rpy="0 0 0" />
      <mass
        value="0.0267240448883812" />
      <inertia
        ixx="1.05776518737304E-05"
        ixy="4.17466317108795E-08"
        ixz="-4.94412707881078E-07"
        iyy="1.02820791329259E-05"
        iyz="5.30501392593403E-07"
        izz="1.56447936575552E-06" />
    </inertial>
    <visual>
      <origin
        xyz="0 0 0"
        rpy="0 0 0" />
      <geometry>
        <mesh
          filename="package://msg_gripper/meshes/jaw1.STL" />
      </geometry>
      <material
        name="">
        <color
          rgba="0.29804 0.29804 0.29804 1" />
      </material>
    </visual>
    <collision>
      <origin
        xyz="0 0 0"
        rpy="0 0 0" />
      <geometry>
        <mesh
          filename="package://msg_gripper/meshes/jaw1.STL" />
      </geometry>
    </collision>
  </link>
  <joint
    name="joint_jaw1"
    type="prismatic">
    <origin
      xyz="0.02835 0 -0.1409"
      rpy="-3.1416 0 3.1416" />
    <parent
      link="gripper" />
    <child
      link="jaw1" />
    <axis
      xyz="0 -1 0" />
    <limit
      lower="-0.052"
      upper="0"
      effort="20"
      velocity="0.1" />
  </joint>
  <link
    name="jaw2">
    <inertial>
      <origin
        xyz="0.000313277058697659 0.0636017321420815 -0.0494862901594326"
        rpy="0 0 0" />
      <mass
        value="0.0267245850480152" />
      <inertia
        ixx="1.05767573086608E-05"
        ixy="-4.18351972636844E-08"
        ixz="-7.32706121136976E-07"
        iyy="1.02816308296904E-05"
        iyz="-5.3239570329707E-07"
        izz="1.56361148863754E-06" />
    </inertial>
    <visual>
      <origin
        xyz="0 0 0"
        rpy="0 0 0" />
      <geometry>
        <mesh
          filename="package://msg_gripper/meshes/jaw2.STL" />
      </geometry>
      <material
        name="">
        <color
          rgba="0.29804 0.29804 0.29804 1" />
      </material>
    </visual>
    <collision>
      <origin
        xyz="0 0 0"
        rpy="0 0 0" />
      <geometry>
        <mesh
          filename="package://msg_gripper/meshes/jaw2.STL" />
      </geometry>
    </collision>
  </link>
  <joint
    name="joint_jaw2" type="prismatic">
    <mimic joint="joint_jaw1" multiplier="-1" offset="0"/>
    <origin
      xyz="0.02835 0 -0.1409"
      rpy="-3.1416 0 3.1416" />
    <parent
      link="gripper" />
    <child
      link="jaw2" />
    <axis
      xyz="0 -1 0" />
    <limit
      lower="0"
      upper="0.052"
      effort="20"
      velocity="0.1" />
  </joint>

  <transmission name="jaw_transmission">
    <type>transmission_interface/SimpleTransmission</type>
    <joint name="joint_jaw1">
      <hardwareInterface>PositionJointInterface</hardwareInterface>
    </joint>
    <actuator name="jaw_motor">
      <hardwareInterface>PositionJointInterface</hardwareInterface>
      <mechanicalReduction>1</mechanicalReduction>
    </actuator>
  </transmission>

</robot>
